2024-09-21 12:39:30,359 | WARNING | Неверный тип данных для объекта Runner
Traceback (most recent call last):
  File "D:\program\PythonProjects\Homework2\Module 12\tests_12_4.py", line 21, in test_run
    object2 = rt_with_exceptions.Runner(28, speed=5)
              ^^^^^^^^^^^^^^^^^^^^^^^^^^^^^^^^^^^^^^
  File "D:\program\PythonProjects\Homework2\Module 12\rt_with_exceptions.py", line 6, in __init__
    raise TypeError(f'Имя может быть только строкой, передано {type(name).__name__}')
TypeError: Имя может быть только строкой, передано int
2024-09-21 12:39:30,359 | WARNING | Неверная скорость для Runner
Traceback (most recent call last):
  File "D:\program\PythonProjects\Homework2\Module 12\tests_12_4.py", line 11, in test_walk
    object1 = rt_with_exceptions.Runner('Nick', speed=-5)
              ^^^^^^^^^^^^^^^^^^^^^^^^^^^^^^^^^^^^^^^^^^^
  File "D:\program\PythonProjects\Homework2\Module 12\rt_with_exceptions.py", line 11, in __init__
    raise ValueError(f'Скорость не может быть отрицательной, сейчас {speed}')
ValueError: Скорость не может быть отрицательной, сейчас -5
